<?xml version='1.0'?>

<robot name="astromech" xmlns:xacro="http://www.ros.org/wiki/xacro">



  <xacro:include filename="$(find astromech_description)/urdf/astromech.gazebo" />
  <!--xacro:include filename="$(find astromech_description)/urdf/materials.xacro" /-->
  <!--xacro:include filename="$(find astromech_description)/urdf/macros.xacro"/--> 
  <xacro:include filename="$(find astromech_description)/urdf/astromech.cameraplugin.xacro" />
  <!--xacro:include filename="$(find astromech_description)/urdf/materials.xacro" /-->
  <xacro:include filename="$(find astromech_description)/urdf/macros.xacro"/> 
  
  <xacro:property name="camera_size" value="0.02"/>
  <xacro:property name="camera_origin_x" value="0.065"/>
  <xacro:property name="camera_origin_y" value="0"/>
  <xacro:property name="camera_origin_z" value="0.025"/>

	<xacro:macro name="default_inertial" params="mass">
    <inertial>
      <mass value="${mass}"/>
      <inertia ixx="1.0" ixy="0.0" ixz="0.0" iyy="1.0" iyz="0.0" izz="1.0"/>
    </inertial>
  </xacro:macro>

<link name="base_link">
<visual>
<geometry>
<cylinder length="0.6" radius="0.2"/>
</geometry>
  <origin rpy="0 0 0" xyz="0 0 0.395"/>
<material name="blue">
<color rgba="0 0 .8 1"/>
</material>
</visual>
</link>
<link name="right_leg">
<visual>
<geometry>
<box size="0.6 .2 .1"/>
</geometry>
<origin rpy="0 1.57075 0" xyz="0 0 -0.3"/>
<material name="white">
<color rgba="1 1 1 1"/>
</material>
</visual>
</link>
<joint name="base_to_right_leg" type="fixed">
<parent link="base_link"/>
<child link="right_leg"/>
<origin xyz="0.22 0 .720"/>
</joint>
<link name="right_base">
<visual>
<geometry>
<box size=".1 0.4 .1"/>
</geometry>
<material name="white"/>
</visual>
</link>
<joint name="right_base_joint" type="fixed">
<parent link="right_leg"/>
<child link="right_base"/>
<origin xyz="0 0 -0.6"/>
</joint>
<link name="right_front_wheel">
<visual>
<geometry>
<sphere  radius="0.035"/>
</geometry>
<material name="black">
<color rgba="0 0 0 1"/>
</material>
</visual>
</link>
<joint name="right_front_wheel_joint" type="continuous">
<axis xyz="0 0 1"/>
<parent link="right_base"/>
<child link="right_front_wheel"/>
<origin rpy="0 1.57075 0" xyz="0 0.133333333333 -0.085"/>
<limit effort="100" velocity="100"/>
<dynamics damping="0.0" friction="0.0"/>
</joint>
<link name="right_back_wheel">
<visual>
<geometry>
<sphere radius="0.035"/>
</geometry>
<material name="black"/>
</visual>
</link>
<joint name="right_back_wheel_joint" type="continuous">
<axis xyz="0 0 1"/>
<parent link="right_base"/>
<child link="right_back_wheel"/>
<origin rpy="0 1.57075 0" xyz="0 -0.133333333333 -0.085"/>
<limit effort="100" velocity="100"/>
<dynamics damping="0.0" friction="0.0"/>
</joint>
<link name="left_leg">
<visual>
<geometry>
<box size="0.6 .2 .1"/>
</geometry>
<origin rpy="0 1.57075 0" xyz="0 0 -0.3"/>
<material name="white"/>
</visual>
</link>
<joint name="base_to_left_leg" type="fixed">
<parent link="base_link"/>
<child link="left_leg"/>
<origin xyz="-0.22 0 .720"/>
</joint>
<link name="left_base">
<visual>
<geometry>
<box size=".1 0.4 .1"/>
</geometry>
<material name="white"/>
</visual>
</link>
<joint name="left_base_joint" type="fixed">
<parent link="left_leg"/>
<child link="left_base"/>
<origin xyz="0 0 -0.6"/>
</joint>
<link name="left_front_wheel">
<visual>
<geometry>
<sphere radius="0.035"/>
</geometry>
<material name="black"/>
</visual>
</link>
<joint name="left_front_wheel_joint" type="continuous">
<axis xyz="0 0 1"/>
<parent link="left_base"/>
<child link="left_front_wheel"/>
<origin rpy="0 1.57075 0" xyz="0 0.133333333333 -0.085"/>
<limit effort="100" velocity="100"/>
<dynamics damping="0.0" friction="0.0"/>
</joint>
<link name="left_back_wheel">
<visual>
<geometry>
<sphere radius="0.035"/>
</geometry>
<material name="black"/>
</visual>
</link>
<joint name="left_back_wheel_joint" type="continuous">
<axis xyz="0 0 1"/>
<parent link="left_base"/>
<child link="left_back_wheel"/>
<origin rpy="0 1.57075 0" xyz="0 -0.133333333333 -0.085"/>
<limit effort="100" velocity="100"/>
<dynamics damping="0.0" friction="0.0"/>
</joint>




<link name="head">
<visual>
<geometry>
<sphere radius="0.2"/>
</geometry>
<material name="white"/>
</visual>
</link>
<joint name="head_swivel" type="continuous">
<parent link="base_link"/>
<child link="head"/>
<axis xyz="0 0 1"/>
<origin xyz="0 0 0.725"/>
</joint>
<link name="box">
<visual>
<geometry>
<box size=".08 .08 .08"/>
</geometry>
<material name="blue"/>
</visual>
</link>
<joint name="tobox" type="fixed">
<parent link="head"/>
<child link="box"/>
<origin xyz="0 0.1414 0.1414"/>
</joint>
 
<!--Camera-->
  <!--link name="camera">
    <visual>
      <geometry>
        <box size="${camera_size} ${camera_size} ${camera_size}"/>
      </geometry>
      <material name="blue"/>
    </visual>
    <collision>
      <geometry>
        <box size="${camera_size} ${camera_size} ${camera_size}"/>
      </geometry>
    </collision>
    <xacro:default_inertial mass="0.02"/>
  </link>

  <joint name="camera_joint" type="fixed">
    <origin xyz="${camera_origin_x} ${camera_origin_y} ${camera_origin_z}" rpy="0 0 0"/>
    <parent link="chassis"/>
    <child link="camera"/>
  </joint-->



</robot>
